Workbook
Name UPDATE: 'Data Sheet'!$E$1

Sheet Profit & Loss
A1: ='Data Sheet'!B1 -> DABUR INDIA LTD | H1: =UPDATE | M1: SCREENER.IN
A3: Narration | B3: ='Data Sheet'!B16 -> 42094 | C3: ='Data Sheet'!C16 -> 42460 | D3: ='Data Sheet'!D16 -> 42825 | E3: ='Data Sheet'!E16 -> 43190 | F3: ='Data Sheet'!F16 -> 43555 | G3: ='Data Sheet'!G16 -> 43921 | H3: ='Data Sheet'!H16 -> 44286 | I3: ='Data Sheet'!I16 -> 44651 | ... K3: ='Data Sheet'!K16 -> 45382 | L3: Trailing | M3: Best Case | N3: Worst Case
A4: Sales | B4: ='Data Sheet'!B17 -> 7795.49 | C4: ='Data Sheet'!C17 -> 7779.66 | D4: ='Data Sheet'!D17 -> 7613.59 | E4: ='Data Sheet'!E17 -> 7721.85 | F4: ='Data Sheet'!F17 -> 8514.99 | G4: ='Data Sheet'!G17 -> 8684.64 | H4: ='Data Sheet'!H17 -> 9561.65 | I4: ='Data Sheet'!I17 -> 10888.68 | ... K4: ='Data Sheet'!K17 -> 12404.01 | L4: =SUM(Quarters!H4:K4) -> 12622.65 | M4: =$K4+M23*K4 -> 13528.154 | N4: =$K4+N23*L4 -> 13072.546
A5: Expenses | B5: =SUM('Data Sheet'!B18,'Data Sheet'!B20:B24, -1*'Data Sheet'!B19) -> 6475.27 | C5: =SUM('Data Sheet'!C18,'Data Sheet'!C20:C24, -1*'Data Sheet'!C19) -> 6261.38 | D5: =SUM('Data Sheet'!D18,'Data Sheet'!D20:D24, -1*'Data Sheet'!D19) -> 6101.98 | E5: =SUM('Data Sheet'!E18,'Data Sheet'!E20:E24, -1*'Data Sheet'!E19) -> 6104.41 | F5: =SUM('Data Sheet'!F18,'Data Sheet'!F20:F24, -1*'Data Sheet'!F19) -> 6775.43 | G5: =SUM('Data Sheet'!G18,'Data Sheet'!G20:G24, -1*'Data Sheet'!G19) -> 6892.3 | H5: =SUM('Data Sheet'!H18,'Data Sheet'!H20:H24, -1*'Data Sheet'!H19) -> 7559.98 | I5: =SUM('Data Sheet'!I18,'Data Sheet'!I20:I24, -1*'Data Sheet'!I19) -> 8636.67 | ... K5: =SUM('Data Sheet'!K18,'Data Sheet'!K20:K24, -1*'Data Sheet'!K19) -> 10004.29 | L5: =SUM(Quarters!H5:K5) -> 10173.12 | M5: =M4-M6 -> 10880.911 | N5: =N4-N6 -> 10535.71
A6: Operating Profit | B6: =B4-B5 -> 1320.22 | C6: =C4-C5 -> 1518.28 | D6: =D4-D5 -> 1511.61 | E6: =E4-E5 -> 1617.44 | F6: =F4-F5 -> 1739.56 | G6: =G4-G5 -> 1792.34 | H6: =H4-H5 -> 2001.67 | I6: =I4-I5 -> 2252.01 | ... K6: =K4-K5 -> 2399.72 | L6: =SUM(Quarters!H6:K6) -> 2449.53 | M6: =M4*M24 -> 2647.2426 | N6: =N4*N24 -> 2536.836
A7: Other Income | B7: ='Data Sheet'!B25 -> 154.24 | C7: ='Data Sheet'!C25 -> 217.19 | D7: ='Data Sheet'!D25 -> 295.93 | E7: ='Data Sheet'!E25 -> 290.88 | F7: ='Data Sheet'!F25 -> 221.79 | G7: ='Data Sheet'!G25 -> 205.29 | H7: ='Data Sheet'!H25 -> 325.29 | I7: ='Data Sheet'!I25 -> 308.16 | ... K7: ='Data Sheet'!K25 -> 482.41 | L7: =SUM(Quarters!H7:K7) -> 502.52 | M7: 0 | N7: 0
A8: Depreciation | B8: ='Data Sheet'!B26 -> 114.98 | C8: ='Data Sheet'!C26 -> 133.19 | D8: ='Data Sheet'!D26 -> 142.86 | E8: ='Data Sheet'!E26 -> 162.18 | F8: ='Data Sheet'!F26 -> 176.9 | G8: ='Data Sheet'!G26 -> 220.45 | H8: ='Data Sheet'!H26 -> 240.13 | I8: ='Data Sheet'!I26 -> 252.89 | ... K8: ='Data Sheet'!K26 -> 399.21 | L8: =SUM(Quarters!H8:K8) -> 411.69 | M8: =+$L8 -> 411.69 | N8: =+$L8 -> 411.69
A9: Interest | B9: ='Data Sheet'!B27 -> 40.12 | C9: ='Data Sheet'!C27 -> 48.48 | D9: ='Data Sheet'!D27 -> 54.03 | E9: ='Data Sheet'!E27 -> 53.05 | F9: ='Data Sheet'!F27 -> 59.58 | G9: ='Data Sheet'!G27 -> 49.54 | H9: ='Data Sheet'!H27 -> 30.81 | I9: ='Data Sheet'!I27 -> 38.6 | ... K9: ='Data Sheet'!K27 -> 124.18 | L9: =SUM(Quarters!H9:K9) -> 132.53 | M9: =+$L9 -> 132.53 | N9: =+$L9 -> 132.53
A10: Profit before tax | B10: ='Data Sheet'!B28 -> 1319.36 | C10: ='Data Sheet'!C28 -> 1553.8 | D10: ='Data Sheet'!D28 -> 1610.65 | E10: ='Data Sheet'!E28 -> 1693.09 | F10: ='Data Sheet'!F28 -> 1724.87 | G10: ='Data Sheet'!G28 -> 1727.64 | H10: ='Data Sheet'!H28 -> 2056.02 | I10: ='Data Sheet'!I28 -> 2268.68 | ... K10: ='Data Sheet'!K28 -> 2358.74 | L10: =SUM(Quarters!H10:K10) -> 2407.83 | M10: =M6+M7-SUM(M8:M9) -> 2103.0226 | N10: =N6+N7-SUM(N8:N9) -> 1992.616
A11: Tax | B11: ='Data Sheet'!B29 -> 250.89 | C11: ='Data Sheet'!C29 -> 299.9 | D11: ='Data Sheet'!D29 -> 330.34 | E11: ='Data Sheet'!E29 -> 335.35 | F11: ='Data Sheet'!F29 -> 278.62 | G11: ='Data Sheet'!G29 -> 279.72 | H11: ='Data Sheet'!H29 -> 361.07 | I11: ='Data Sheet'!I29 -> 526.38 | ... K11: ='Data Sheet'!K29 -> 547.43 | L11: =SUM(Quarters!H11:K11) -> 558.78 | M11: =IF($L10>0,$L11/$L10,0) -> 0.23206788 | N11: =IF($L10>0,$L11/$L10,0) -> 0.23206788
A12: Net profit | B12: ='Data Sheet'!B30 -> 1065.83 | C12: ='Data Sheet'!C30 -> 1251.15 | D12: ='Data Sheet'!D30 -> 1276.94 | E12: ='Data Sheet'!E30 -> 1354.39 | F12: ='Data Sheet'!F30 -> 1442.33 | G12: ='Data Sheet'!G30 -> 1444.96 | H12: ='Data Sheet'!H30 -> 1693.3 | I12: ='Data Sheet'!I30 -> 1739.22 | ... K12: ='Data Sheet'!K30 -> 1842.68 | L12: =SUM(Quarters!H12:K12) -> 1878.92 | M12: =M10-M11*M10 -> 1614.9786 | N12: =N10-N11*N10 -> 1530.1938
A13: EPS | B13: =IF('Data Sheet'!B93>0,B12/'Data Sheet'!B93,0) -> 6.0679192 | C13: =IF('Data Sheet'!C93>0,C12/'Data Sheet'!C93,0) -> 7.1124439 | D13: =IF('Data Sheet'!D93>0,D12/'Data Sheet'!D93,0) -> 7.2491626 | E13: =IF('Data Sheet'!E93>0,E12/'Data Sheet'!E93,0) -> 7.6888447 | F13: =IF('Data Sheet'!F93>0,F12/'Data Sheet'!F93,0) -> 8.1658269 | G13: =IF('Data Sheet'!G93>0,G12/'Data Sheet'!G93,0) -> 8.1770132 | H13: =IF('Data Sheet'!H93>0,H12/'Data Sheet'!H93,0) -> 9.5807401 | I13: =IF('Data Sheet'!I93>0,I12/'Data Sheet'!I93,0) -> 9.8377736 | ... K13: =IF('Data Sheet'!K93>0,K12/'Data Sheet'!K93,0) -> 10.398871 | L13: =IF('Data Sheet'!$B6>0,'Profit & Loss'!L12/'Data Sheet'!$B6,0) -> 10.601529 | M13: =IF('Data Sheet'!$B6>0,'Profit & Loss'!M12/'Data Sheet'!$B6,0) -> 9.1122785 | N13: =IF('Data Sheet'!$B6>0,'Profit & Loss'!N12/'Data Sheet'!$B6,0) -> 8.6338931
A14: Price to earning | B14: =IF(B15>0,B15/B13,"") -> 43.762943 | C14: =IF(C15>0,C15/C13,"") -> 35.135602 | D14: =IF(D15>0,D15/D13,"") -> 38.259591 | E14: =IF(E15>0,E15/E13,"") -> 42.711228 | F14: =IF(F15>0,F15/F13,"") -> 50.062291 | G14: =IF(G15>0,G15/G13,"") -> 55.038434 | H14: =IF(H15>0,H15/H13,"") -> 56.415266 | I14: =IF(I15>0,I15/I13,"") -> 54.504202 | ... K14: =IF(K15>0,K15/K13,"") -> 50.308344 | L14: =IF(L13>0,L15/L13,0) -> 59.019788 | M14: =M25 -> 59.019788 | N14: =N25 -> 49.25193
A15: Price | B15: ='Data Sheet'!B90 -> 265.55 | C15: ='Data Sheet'!C90 -> 249.9 | D15: ='Data Sheet'!D90 -> 277.35 | E15: ='Data Sheet'!E90 -> 328.4 | F15: ='Data Sheet'!F90 -> 408.8 | G15: ='Data Sheet'!G90 -> 450.05 | H15: ='Data Sheet'!H90 -> 540.5 | I15: ='Data Sheet'!I90 -> 536.2 | ... K15: ='Data Sheet'!K90 -> 523.15 | L15: ='Data Sheet'!B8 -> 625.7 | M15: =M13*M14 -> 537.80475 | N15: =N13*N14 -> 425.2359
A17: RATIOS:
A18: Dividend Payout | B18: =IF('Data Sheet'!B30>0, 'Data Sheet'!B31/'Data Sheet'!B30, 0) -> 0.32960228 | C18: =IF('Data Sheet'!C30>0, 'Data Sheet'!C31/'Data Sheet'!C30, 0) -> 0.31634896 | D18: =IF('Data Sheet'!D30>0, 'Data Sheet'!D31/'Data Sheet'!D30, 0) -> 0.31038263 | E18: =IF('Data Sheet'!E30>0, 'Data Sheet'!E31/'Data Sheet'!E30, 0) -> 0.81286779 | F18: =IF('Data Sheet'!F30>0, 'Data Sheet'!F31/'Data Sheet'!F30, 0) -> 0.33676759 | G18: =IF('Data Sheet'!G30>0, 'Data Sheet'!G31/'Data Sheet'!G30, 0) -> 0.36688213 | H18: =IF('Data Sheet'!H30>0, 'Data Sheet'!H31/'Data Sheet'!H30, 0) -> 0.49578929 | I18: =IF('Data Sheet'!I30>0, 'Data Sheet'!I31/'Data Sheet'!I30, 0) -> 0.52857603 | ... K18: =IF('Data Sheet'!K30>0, 'Data Sheet'!K31/'Data Sheet'!K30, 0) -> 0.52890355
A19: OPM | B19: =IF(B6>0,B6/B4,0) -> 0.1693569 | C19: =IF(C6>0,C6/C4,0) -> 0.1951602 | D19: =IF(D6>0,D6/D4,0) -> 0.19854103 | E19: =IF(E6>0,E6/E4,0) -> 0.20946276 | F19: =IF(F6>0,F6/F4,0) -> 0.20429384 | G19: =IF(G6>0,G6/G4,0) -> 0.20638046 | H19: =IF(H6>0,H6/H4,0) -> 0.20934358 | I19: =IF(I6>0,I6/I4,0) -> 0.20682121 | ... L19: =IF(L6>0,L6/L4,0) -> 0.1940583
G22: TRENDS: | H22: 10 YEARS | I22: 7 YEARS | J22: 5 YEARS | K22: 3 YEARS | L22: RECENT | M22: BEST | N22: WORST
G23: Sales Growth | H23: =IF(B4=0,"",POWER($K4/B4,1/9)-1) -> 0.052963186 | I23: =IF(D4=0,"",POWER($K4/D4,1/7)-1) -> 0.072214814 | J23: =IF(F4=0,"",POWER($K4/F4,1/5)-1) -> 0.078141077 | K23: =IF(H4=0,"",POWER($K4/H4, 1/3)-1) -> 0.090627444 | L23: =IF(ISERROR(MAX(IF(J4=0,"",(K4-J4)/J4),IF(K4=0,"",(L4-K4)/K4))),"",MAX(IF(J4=0,"",(K4-J4)/J4),IF(K4=0,"",(L4-K4)/K4))) -> 0.075813386 | M23: =MAX(K23:L23) -> 0.090627444 | N23: =MIN(H23:L23) -> 0.052963186
G24: OPM | H24: =IF(SUM(B4:$K$4)=0,"",SUMPRODUCT(B19:$K$19,B4:$K$4)/SUM(B4:$K$4)) -> 0.19801556 | I24: =IF(SUM(E4:$K$4)=0,"",SUMPRODUCT(E19:$K$19,E4:$K$4)/SUM(E4:$K$4)) -> 0.20150187 | J24: =IF(SUM(G4:$K$4)=0,"",SUMPRODUCT(G19:$K$19,G4:$K$4)/SUM(G4:$K$4)) -> 0.19989553 | K24: =IF(SUM(I4:$K$4)=0, "", SUMPRODUCT(I19:$K$19,I4:$K$4)/SUM(I4:$K$4)) -> 0.19568395 | L24: =L19 -> 0.1940583 | M24: =MAX(K24:L24) -> 0.19568395 | N24: =MIN(H24:L24) -> 0.1940583
G25: Price to Earning | H25: =IF(ISERROR(AVERAGEIF(B14:$L14,">0")),"",AVERAGEIF(B14:$L14,">0")) -> 49.25193 | I25: =IF(ISERROR(AVERAGEIF(E14:$L14,">0")),"",AVERAGEIF(E14:$L14,">0")) -> 53.076637 | J25: =IF(ISERROR(AVERAGEIF(G14:$L14,">0")),"",AVERAGEIF(G14:$L14,">0")) -> 55.306596 | K25: =IF(ISERROR(AVERAGEIF(I14:$L14,">0")),"",AVERAGEIF(I14:$L14,">0")) -> 55.096469 | L25: =L14 -> 59.019788 | M25: =MAX(K25:L25) -> 59.019788 | N25: =MIN(H25:L25) -> 49.25193

Sheet Quarters
A1: ='Profit & Loss'!A1 -> DABUR INDIA LTD | E1: =UPDATE | J1: SCREENER.IN
A3: Narration | B3: ='Data Sheet'!B41 -> 44651 | C3: ='Data Sheet'!C41 -> 44742 | D3: ='Data Sheet'!D41 -> 44834 | E3: ='Data Sheet'!E41 -> 44926 | F3: ='Data Sheet'!F41 -> 45016 | G3: ='Data Sheet'!G41 -> 45107 | H3: ='Data Sheet'!H41 -> 45199 | I3: ='Data Sheet'!I41 -> 45291 | ... K3: ='Data Sheet'!K41 -> 45473
A4: Sales | B4: ='Data Sheet'!B42 -> 2517.81 | C4: ='Data Sheet'!C42 -> 2822.43 | D4: ='Data Sheet'!D42 -> 2986.49 | E4: ='Data Sheet'!E42 -> 3043.17 | F4: ='Data Sheet'!F42 -> 2677.8 | G4: ='Data Sheet'!G42 -> 3130.47 | H4: ='Data Sheet'!H42 -> 3203.84 | I4: ='Data Sheet'!I42 -> 3255.06 | ... K4: ='Data Sheet'!K42 -> 3349.11
A5: Expenses | B5: ='Data Sheet'!B43 -> 2065.44 | C5: ='Data Sheet'!C43 -> 2279.11 | D5: ='Data Sheet'!D43 -> 2386.09 | E5: ='Data Sheet'!E43 -> 2434.05 | F5: ='Data Sheet'!F43 -> 2268.15 | G5: ='Data Sheet'!G43 -> 2525.94 | H5: ='Data Sheet'!H43 -> 2542.97 | I5: ='Data Sheet'!I43 -> 2587.64 | ... K5: ='Data Sheet'!K43 -> 2694.28
A6: Operating Profit | B6: ='Data Sheet'!B50 -> 452.37 | C6: ='Data Sheet'!C50 -> 543.32 | D6: ='Data Sheet'!D50 -> 600.4 | E6: ='Data Sheet'!E50 -> 609.12 | F6: ='Data Sheet'!F50 -> 409.65 | G6: ='Data Sheet'!G50 -> 604.53 | H6: ='Data Sheet'!H50 -> 660.87 | I6: ='Data Sheet'!I50 -> 667.42 | ... K6: ='Data Sheet'!K50 -> 654.83
A7: Other Income | B7: ='Data Sheet'!B44 -> 14.14 | C7: ='Data Sheet'!C44 -> 100.55 | D7: ='Data Sheet'!D44 -> 123.28 | E7: ='Data Sheet'!E44 -> 100.84 | F7: ='Data Sheet'!F44 -> 120.72 | G7: ='Data Sheet'!G44 -> 109.78 | H7: ='Data Sheet'!H44 -> 116.9 | I7: ='Data Sheet'!I44 -> 127.37 | ... K7: ='Data Sheet'!K44 -> 129.4
A8: Depreciation | B8: ='Data Sheet'!B45 -> 65.05 | C8: ='Data Sheet'!C45 -> 67.6 | D8: ='Data Sheet'!D45 -> 70.47 | E8: ='Data Sheet'!E45 -> 70.89 | F8: ='Data Sheet'!F45 -> 102 | G8: ='Data Sheet'!G45 -> 96.64 | H8: ='Data Sheet'!H45 -> 98.32 | I8: ='Data Sheet'!I45 -> 96.89 | ... K8: ='Data Sheet'!K45 -> 109.12
A9: Interest | B9: ='Data Sheet'!B46 -> 11.75 | C9: ='Data Sheet'!C46 -> 12.15 | D9: ='Data Sheet'!D46 -> 15.06 | E9: ='Data Sheet'!E46 -> 18.91 | F9: ='Data Sheet'!F46 -> 32.12 | G9: ='Data Sheet'!G46 -> 24.31 | H9: ='Data Sheet'!H46 -> 28.14 | I9: ='Data Sheet'!I46 -> 36.49 | ... K9: ='Data Sheet'!K46 -> 32.66
A10: Profit before tax | B10: ='Data Sheet'!B47 -> 389.71 | C10: ='Data Sheet'!C47 -> 564.12 | D10: ='Data Sheet'!D47 -> 638.15 | E10: ='Data Sheet'!E47 -> 620.16 | F10: ='Data Sheet'!F47 -> 396.25 | G10: ='Data Sheet'!G47 -> 593.36 | H10: ='Data Sheet'!H47 -> 651.31 | I10: ='Data Sheet'!I47 -> 661.41 | ... K10: ='Data Sheet'!K47 -> 642.45
A11: Tax | B11: ='Data Sheet'!B48 -> 95.37 | C11: ='Data Sheet'!C48 -> 123.06 | D11: ='Data Sheet'!D48 -> 147.29 | E11: ='Data Sheet'!E48 -> 143.51 | F11: ='Data Sheet'!F48 -> 103.49 | G11: ='Data Sheet'!G48 -> 136.75 | H11: ='Data Sheet'!H48 -> 144.27 | I11: ='Data Sheet'!I48 -> 154.97 | ... K11: ='Data Sheet'!K48 -> 148.1
A12: Net profit | B12: ='Data Sheet'!B49 -> 294.22 | C12: ='Data Sheet'!C49 -> 440.32 | D12: ='Data Sheet'!D49 -> 490.06 | E12: ='Data Sheet'!E49 -> 475.94 | F12: ='Data Sheet'!F49 -> 300.83 | G12: ='Data Sheet'!G49 -> 463.88 | H12: ='Data Sheet'!H49 -> 515.05 | I12: ='Data Sheet'!I49 -> 514.22 | ... K12: ='Data Sheet'!K49 -> 500.12
A14: OPM | B14: =IF(B4>0,B6/B4,"") -> 0.17966804 | C14: =IF(C4>0,C6/C4,"") -> 0.19250079 | D14: =IF(D4>0,D6/D4,"") -> 0.20103868 | E14: =IF(E4>0,E6/E4,"") -> 0.2001597 | F14: =IF(F4>0,F6/F4,"") -> 0.15298006 | G14: =IF(G4>0,G6/G4,"") -> 0.19311158 | H14: =IF(H4>0,H6/H4,"") -> 0.20627435 | I14: =IF(I4>0,I6/I4,"") -> 0.20504077 | ... K14: =IF(K4>0,K6/K4,"") -> 0.19552359

Sheet Balance Sheet
A1: ='Profit & Loss'!A1 -> DABUR INDIA LTD | E1: =UPDATE | J1: SCREENER.IN
A3: Narration | B3: ='Data Sheet'!B56 -> 42094 | C3: ='Data Sheet'!C56 -> 42460 | D3: ='Data Sheet'!D56 -> 42825 | E3: ='Data Sheet'!E56 -> 43190 | F3: ='Data Sheet'!F56 -> 43555 | G3: ='Data Sheet'!G56 -> 43921 | H3: ='Data Sheet'!H56 -> 44286 | I3: ='Data Sheet'!I56 -> 44651 | ... K3: ='Data Sheet'!K56 -> 45382
A4: Equity Share Capital | B4: ='Data Sheet'!B57 -> 175.65 | C4: ='Data Sheet'!C57 -> 175.91 | D4: ='Data Sheet'!D57 -> 176.15 | E4: ='Data Sheet'!E57 -> 176.15 | F4: ='Data Sheet'!F57 -> 176.63 | G4: ='Data Sheet'!G57 -> 176.71 | H4: ='Data Sheet'!H57 -> 176.74 | I4: ='Data Sheet'!I57 -> 176.79 | ... K4: ='Data Sheet'!K57 -> 177.2
A5: Reserves | B5: ='Data Sheet'!B58 -> 3178.49 | C5: ='Data Sheet'!C58 -> 3994.7 | D5: ='Data Sheet'!D58 -> 4671.24 | E5: ='Data Sheet'!E58 -> 5530.37 | F5: ='Data Sheet'!F58 -> 5455.05 | G5: ='Data Sheet'!G58 -> 6429.04 | H5: ='Data Sheet'!H58 -> 7486.79 | I5: ='Data Sheet'!I58 -> 8204.51 | ... K5: ='Data Sheet'!K58 -> 9689.1
A6: Borrowings | B6: ='Data Sheet'!B59 -> 733.56 | C6: ='Data Sheet'!C59 -> 805.22 | D6: ='Data Sheet'!D59 -> 975 | E6: ='Data Sheet'!E59 -> 937.59 | F6: ='Data Sheet'!F59 -> 699.37 | G6: ='Data Sheet'!G59 -> 521.99 | H6: ='Data Sheet'!H59 -> 509.06 | I6: ='Data Sheet'!I59 -> 1030.1 | ... K6: ='Data Sheet'!K59 -> 1365.09
A7: Other Liabilities | B7: ='Data Sheet'!B60 -> 2018.58 | C7: ='Data Sheet'!C60 -> 1956.47 | D7: ='Data Sheet'!D60 -> 1909.85 | E7: ='Data Sheet'!E60 -> 2057.52 | F7: ='Data Sheet'!F60 -> 2105.59 | G7: ='Data Sheet'!G60 -> 2208.84 | H7: ='Data Sheet'!H60 -> 2660.63 | I7: ='Data Sheet'!I60 -> 2872.46 | ... K7: ='Data Sheet'!K60 -> 3884.97
A8: Total | B8: ='Data Sheet'!B61 -> 6106.28 | C8: ='Data Sheet'!C61 -> 6932.3 | D8: ='Data Sheet'!D61 -> 7732.24 | E8: ='Data Sheet'!E61 -> 8701.63 | F8: ='Data Sheet'!F61 -> 8436.64 | G8: ='Data Sheet'!G61 -> 9336.58 | H8: ='Data Sheet'!H61 -> 10833.22 | I8: ='Data Sheet'!I61 -> 12283.86 | ... K8: ='Data Sheet'!K61 -> 15116.36
A10: Net Block | B10: ='Data Sheet'!B62 -> 1877.13 | C10: ='Data Sheet'!C62 -> 1667.4 | D10: ='Data Sheet'!D62 -> 1958.4 | E10: ='Data Sheet'!E62 -> 2028.11 | F10: ='Data Sheet'!F62 -> 1969.06 | G10: ='Data Sheet'!G62 -> 2252.68 | H10: ='Data Sheet'!H62 -> 2242.92 | I10: ='Data Sheet'!I62 -> 2307.9 | ... K10: ='Data Sheet'!K62 -> 3815
A11: Capital Work in Progress | B11: ='Data Sheet'!B63 -> 50.3 | C11: ='Data Sheet'!C63 -> 44.8 | D11: ='Data Sheet'!D63 -> 42.1 | E11: ='Data Sheet'!E63 -> 41.51 | F11: ='Data Sheet'!F63 -> 63.76 | G11: ='Data Sheet'!G63 -> 146.57 | H11: ='Data Sheet'!H63 -> 147.3 | I11: ='Data Sheet'!I63 -> 167.5 | ... K11: ='Data Sheet'!K63 -> 232.23
A12: Investments | B12: ='Data Sheet'!B64 -> 1813.37 | C12: ='Data Sheet'!C64 -> 2690.74 | D12: ='Data Sheet'!D64 -> 3240.16 | E12: ='Data Sheet'!E64 -> 3805.17 | F12: ='Data Sheet'!F64 -> 3358.76 | G12: ='Data Sheet'!G64 -> 2800.26 | H12: ='Data Sheet'!H64 -> 4159.63 | I12: ='Data Sheet'!I64 -> 6219.62 | ... K12: ='Data Sheet'!K64 -> 6932.69
A13: Other Assets | B13: ='Data Sheet'!B65 -> 2365.48 | C13: ='Data Sheet'!C65 -> 2529.36 | D13: ='Data Sheet'!D65 -> 2491.58 | E13: ='Data Sheet'!E65 -> 2826.84 | F13: ='Data Sheet'!F65 -> 3045.06 | G13: ='Data Sheet'!G65 -> 4137.07 | H13: ='Data Sheet'!H65 -> 4283.37 | I13: ='Data Sheet'!I65 -> 3588.84 | ... K13: ='Data Sheet'!K65 -> 4136.44
A14: Total | B14: ='Data Sheet'!B66 -> 6106.28 | C14: ='Data Sheet'!C66 -> 6932.3 | D14: ='Data Sheet'!D66 -> 7732.24 | E14: ='Data Sheet'!E66 -> 8701.63 | F14: ='Data Sheet'!F66 -> 8436.64 | G14: ='Data Sheet'!G66 -> 9336.58 | H14: ='Data Sheet'!H66 -> 10833.22 | I14: ='Data Sheet'!I66 -> 12283.86 | ... K14: ='Data Sheet'!K66 -> 15116.36
A16: Working Capital | B16: =B13-B7 -> 346.9 | C16: =C13-C7 -> 572.89 | D16: =D13-D7 -> 581.73 | E16: =E13-E7 -> 769.32 | F16: =F13-F7 -> 939.47 | G16: =G13-G7 -> 1928.23 | H16: =H13-H7 -> 1622.74 | I16: =I13-I7 -> 716.38 | ... K16: =K13-K7 -> 251.47
A17: Debtors | B17: ='Data Sheet'!B67 -> 710.84 | C17: ='Data Sheet'!C67 -> 809.2 | D17: ='Data Sheet'!D67 -> 650.42 | E17: ='Data Sheet'!E67 -> 706.08 | F17: ='Data Sheet'!F67 -> 833.56 | G17: ='Data Sheet'!G67 -> 813.89 | H17: ='Data Sheet'!H67 -> 561.58 | I17: ='Data Sheet'!I67 -> 646.15 | ... K17: ='Data Sheet'!K67 -> 898.72
A18: Inventory | B18: ='Data Sheet'!B68 -> 973.27 | C18: ='Data Sheet'!C68 -> 1096.5 | D18: ='Data Sheet'!D68 -> 1106.71 | E18: ='Data Sheet'!E68 -> 1256.18 | F18: ='Data Sheet'!F68 -> 1300.53 | G18: ='Data Sheet'!G68 -> 1379.57 | H18: ='Data Sheet'!H68 -> 1734.28 | I18: ='Data Sheet'!I68 -> 1911.37 | ... K18: ='Data Sheet'!K68 -> 1946.97
A20: Debtor Days | B20: =IF('Profit & Loss'!B4>0,'Balance Sheet'!B17/('Profit & Loss'!B4/365),0) -> 33.282911 | C20: =IF('Profit & Loss'!C4>0,'Balance Sheet'!C17/('Profit & Loss'!C4/365),0) -> 37.965412 | D20: =IF('Profit & Loss'!D4>0,'Balance Sheet'!D17/('Profit & Loss'!D4/365),0) -> 31.181519 | E20: =IF('Profit & Loss'!E4>0,'Balance Sheet'!E17/('Profit & Loss'!E4/365),0) -> 33.375318 | F20: =IF('Profit & Loss'!F4>0,'Balance Sheet'!F17/('Profit & Loss'!F4/365),0) -> 35.731034 | G20: =IF('Profit & Loss'!G4>0,'Balance Sheet'!G17/('Profit & Loss'!G4/365),0) -> 34.206352 | H20: =IF('Profit & Loss'!H4>0,'Balance Sheet'!H17/('Profit & Loss'!H4/365),0) -> 21.437377 | I20: =IF('Profit & Loss'!I4>0,'Balance Sheet'!I17/('Profit & Loss'!I4/365),0) -> 21.659627 | ... K20: =IF('Profit & Loss'!K4>0,'Balance Sheet'!K17/('Profit & Loss'!K4/365),0) -> 26.445706
A21: Inventory Turnover | B21: =IF('Balance Sheet'!B18>0,'Profit & Loss'!B4/'Balance Sheet'!B18,0) -> 8.0095862 | C21: =IF('Balance Sheet'!C18>0,'Profit & Loss'!C4/'Balance Sheet'!C18,0) -> 7.0949932 | D21: =IF('Balance Sheet'!D18>0,'Profit & Loss'!D4/'Balance Sheet'!D18,0) -> 6.8794806 | E21: =IF('Balance Sheet'!E18>0,'Profit & Loss'!E4/'Balance Sheet'!E18,0) -> 6.1470888 | F21: =IF('Balance Sheet'!F18>0,'Profit & Loss'!F4/'Balance Sheet'!F18,0) -> 6.547323 | G21: =IF('Balance Sheet'!G18>0,'Profit & Loss'!G4/'Balance Sheet'!G18,0) -> 6.2951789 | H21: =IF('Balance Sheet'!H18>0,'Profit & Loss'!H4/'Balance Sheet'!H18,0) -> 5.5133254 | I21: =IF('Balance Sheet'!I18>0,'Profit & Loss'!I4/'Balance Sheet'!I18,0) -> 5.6967934 | ... K21: =IF('Balance Sheet'!K18>0,'Profit & Loss'!K4/'Balance Sheet'!K18,0) -> 6.3709302
A23: Return on Equity | B23: =IF(SUM('Balance Sheet'!B4:B5)>0,'Profit & Loss'!B12/SUM('Balance Sheet'!B4:B5),"") -> 0.31776551 | C23: =IF(SUM('Balance Sheet'!C4:C5)>0,'Profit & Loss'!C12/SUM('Balance Sheet'!C4:C5),"") -> 0.29999209 | D23: =IF(SUM('Balance Sheet'!D4:D5)>0,'Profit & Loss'!D12/SUM('Balance Sheet'!D4:D5),"") -> 0.26342836 | E23: =IF(SUM('Balance Sheet'!E4:E5)>0,'Profit & Loss'!E12/SUM('Balance Sheet'!E4:E5),"") -> 0.2373408 | F23: =IF(SUM('Balance Sheet'!F4:F5)>0,'Profit & Loss'!F12/SUM('Balance Sheet'!F4:F5),"") -> 0.25611008 | G23: =IF(SUM('Balance Sheet'!G4:G5)>0,'Profit & Loss'!G12/SUM('Balance Sheet'!G4:G5),"") -> 0.21874276 | H23: =IF(SUM('Balance Sheet'!H4:H5)>0,'Profit & Loss'!H12/SUM('Balance Sheet'!H4:H5),"") -> 0.22095562 | I23: =IF(SUM('Balance Sheet'!I4:I5)>0,'Profit & Loss'!I12/SUM('Balance Sheet'!I4:I5),"") -> 0.20751196 | ... K23: =IF(SUM('Balance Sheet'!K4:K5)>0,'Profit & Loss'!K12/SUM('Balance Sheet'!K4:K5),"") -> 0.18676505
A24: Return on Capital Emp | C24: =IF((B4+B5+B6+C4+C5+C6)>0,('Profit & Loss'!C10+'Profit & Loss'!C9)*2/(B4+B5+B6+C4+C5+C6),"") -> 0.35356644 | D24: =IF((C4+C5+C6+D4+D5+D6)>0,('Profit & Loss'!D10+'Profit & Loss'!D9)*2/(C4+C5+C6+D4+D5+D6),"") -> 0.30832489 | E24: =IF((D4+D5+D6+E4+E5+E6)>0,('Profit & Loss'!E10+'Profit & Loss'!E9)*2/(D4+D5+D6+E4+E5+E6),"") -> 0.28013316 | F24: =IF((E4+E5+E6+F4+F5+F6)>0,('Profit & Loss'!F10+'Profit & Loss'!F9)*2/(E4+E5+E6+F4+F5+F6),"") -> 0.27505634 | G24: =IF((F4+F5+F6+G4+G5+G6)>0,('Profit & Loss'!G10+'Profit & Loss'!G9)*2/(F4+F5+F6+G4+G5+G6),"") -> 0.26409209 | H24: =IF((G4+G5+G6+H4+H5+H6)>0,('Profit & Loss'!H10+'Profit & Loss'!H9)*2/(G4+G5+G6+H4+H5+H6),"") -> 0.27278235 | I24: =IF((H4+H5+H6+I4+I5+I6)>0,('Profit & Loss'!I10+'Profit & Loss'!I9)*2/(H4+H5+H6+I4+I5+I6),"") -> 0.26242963 | J24: =IF((I4+I5+I6+J4+J5+J6)>0,('Profit & Loss'!J10+'Profit & Loss'!J9)*2/(I4+I5+I6+J4+J5+J6),"") -> 0.23487751 | K24: =IF((J4+J5+J6+K4+K5+K6)>0,('Profit & Loss'!K10+'Profit & Loss'!K9)*2/(J4+J5+J6+K4+K5+K6),"") -> 0.23228262

Sheet Cash Flow
A1: ='Balance Sheet'!A1 -> DABUR INDIA LTD | E1: =UPDATE | J1: SCREENER.IN
A3: Narration | B3: ='Data Sheet'!B81 -> 42094 | C3: ='Data Sheet'!C81 -> 42460 | D3: ='Data Sheet'!D81 -> 42825 | E3: ='Data Sheet'!E81 -> 43190 | F3: ='Data Sheet'!F81 -> 43555 | G3: ='Data Sheet'!G81 -> 43921 | H3: ='Data Sheet'!H81 -> 44286 | I3: ='Data Sheet'!I81 -> 44651 | ... K3: ='Data Sheet'!K81 -> 45382
A4: Cash from Operating Activity | B4: ='Data Sheet'!B82 -> 1047.21 | C4: ='Data Sheet'!C82 -> 1186.99 | D4: ='Data Sheet'!D82 -> 1226.94 | E4: ='Data Sheet'!E82 -> 1091.5 | F4: ='Data Sheet'!F82 -> 1499.13 | G4: ='Data Sheet'!G82 -> 1613.62 | H4: ='Data Sheet'!H82 -> 2114.67 | I4: ='Data Sheet'!I82 -> 1802.33 | ... K4: ='Data Sheet'!K82 -> 2013.47
A5: Cash from Investing Activity | B5: ='Data Sheet'!B83 -> -875.9 | C5: ='Data Sheet'!C83 -> -730.33 | D5: ='Data Sheet'!D83 -> -807.07 | E5: ='Data Sheet'!E83 -> -540.93 | F5: ='Data Sheet'!F83 -> 337.58 | G5: ='Data Sheet'!G83 -> -516.63 | H5: ='Data Sheet'!H83 -> -1404.22 | I5: ='Data Sheet'!I83 -> -1273.45 | ... K5: ='Data Sheet'!K83 -> -971.04
A6: Cash from Financing Activity | B6: ='Data Sheet'!B84 -> -416.77 | C6: ='Data Sheet'!C84 -> -374.31 | D6: ='Data Sheet'!D84 -> -338.97 | E6: ='Data Sheet'!E84 -> -577.11 | F6: ='Data Sheet'!F84 -> -1888.2 | G6: ='Data Sheet'!G84 -> -1042.97 | H6: ='Data Sheet'!H84 -> -613.41 | I6: ='Data Sheet'!I84 -> -490.49 | ... K6: ='Data Sheet'!K84 -> -1161.18
A7: Net Cash Flow | B7: ='Data Sheet'!B85 -> -245.46 | C7: ='Data Sheet'!C85 -> 82.35 | D7: ='Data Sheet'!D85 -> 80.9 | E7: ='Data Sheet'!E85 -> -26.54 | F7: ='Data Sheet'!F85 -> -51.49 | G7: ='Data Sheet'!G85 -> 54.02 | H7: ='Data Sheet'!H85 -> 97.04 | I7: ='Data Sheet'!I85 -> 38.39 | ... K7: ='Data Sheet'!K85 -> -118.75

Sheet Customization
A1: How to use it?
A3: You can customize this workbook as you want.
B4: You can add custom formating, add conditional formating, add your own formulas… do ANYTHING.
B5: Please don't edit the "Data Sheet" only.
A7: After customization, you can upload this back on Screener.
B8: Upload on: | C8: https://www.screener.in/excel/
A10: Download your customized workbooks now onwards.
B11: Now whenever you will "Export to excel" from Screener, it will export your customized file.
A14: TESTING:
B15: This is a testing feature currently.
B16: You can report any formula errors on the worksheet at: support@screener.in

Sheet Data Room>

Sheet Raw FS
B2: Particulars | C2: 42064 | D2: 42430 | E2: 42795 | F2: 43160 | G2: 43525 | H2: 43891 | I2: 44256 | J2: 44621 | K2: 44986 | L2: 45352
B3: Equity Capital | C3: 176 | D3: 176 | E3: 176 | F3: 176 | G3: 177 | H3: 177 | I3: 177 | J3: 177 | K3: 177 | L3: 177
B4: Reserves | C4: 3178 | D4: 3995 | E4: 4671 | F4: 5530 | G4: 5455 | H4: 6429 | I4: 7487 | J4: 8205 | K4: 8796 | L4: 9689
B5: Borrowings -
B6: Short Term Borrowing | C6: 211 | D6: 342 | E6: 470 | F6: 364 | G6: 26 | H6: 163 | I6: 1 | J6: 250 | K6: 299 | L6: 536
B7: Long Term Borrowing | C7: 523 | D7: 450 | E7: 440 | F7: 464 | G7: 498 | H7: 304 | I7: 349 | J7: 617 | K7: 700 | L7: 622
B8: Lease Liabilities | C8: 0 | D8: 0 | E8: 0 | F8: 0 | G8: 0 | H8: 0 | I8: 159 | J8: 162 | K8: 175 | L8: 207
B9: Other Borrowings | C9: 0 | D9: 13 | E9: 64 | F9: 109 | G9: 175 | H9: 55 | I9: 0 | J9: 0 | K9: 0 | L9: 0
B10: Other Liabilities -
B11: Non controlling int | C11: 18 | D11: 22 | E11: 25 | F11: 27 | G11: 31 | H11: 36 | I11: 37 | J11: 41 | K11: 468 | L11: 437 | O11: If this sheet is touched then its over for me
B12: Trade Payables | C12: 1096 | D12: 1330 | E12: 1310 | F12: 1410 | G12: 1455 | H12: 1482 | I12: 1915 | J12: 2018 | K12: 2187 | L12: 2422
B13: Advance from Customers | C13: 42 | D13: 35 | E13: 18 | F13: 25 | G13: 28 | H13: 30 | I13: 43 | J13: 37 | K13: 9 | L13: 33
B14: Other liability items | C14: 863 | D14: 569 | E14: 557 | F14: 596 | G14: 591 | H14: 660 | I14: 666 | J14: 777 | K14: 842 | L14: 994
B15: Total Liabilities | C15: =SUM(C3:C14) -> 6107 | D15: =SUM(D3:D14) -> 6932 | E15: =SUM(E3:E14) -> 7731 | F15: =SUM(F3:F14) -> 8701 | G15: =SUM(G3:G14) -> 8436 | H15: =SUM(H3:H14) -> 9336 | I15: =SUM(I3:I14) -> 10834 | J15: =SUM(J3:J14) -> 12284 | ... L15: =SUM(L3:L14) -> 15117
B17: Fixed Assets -
B18: Land | C18: 92 | D18: 80 | E18: 98 | F18: 108 | G18: 108 | H18: 103 | I18: 93 | J18: 123 | K18: 141 | L18: 145
B19: Building | C19: 622 | D19: 629 | E19: 714 | F19: 763 | G19: 788 | H19: 1054 | I19: 1057 | J19: 1144 | K19: 1279 | L19: 1513
B20: Plant Machinery | C20: 985 | D20: 1122 | E20: 1303 | F20: 1431 | G20: 1527 | H20: 1719 | I20: 1862 | J20: 2074 | K20: 2408 | L20: 2775
B21: Equipments | C21: 53 | D21: 58 | E21: 62 | F21: 59 | G21: 68 | H21: 69 | I21: 73 | J21: 78 | K21: 88 | L21: 93
B22: Furniture n fittings | C22: 81 | D22: 89 | E22: 94 | F22: 104 | G22: 113 | H22: 126 | I22: 129 | J22: 134 | K22: 148 | L22: 159
B23: Vehicles | C23: 31 | D23: 35 | E23: 35 | F23: 42 | G23: 44 | H23: 45 | I23: 45 | J23: 47 | K23: 43 | L23: 44
B24: Intangible Assets | C24: 634 | D24: 425 | E24: 425 | F24: 426 | G24: 367 | H24: 374 | I24: 375 | J24: 291 | K24: 1322 | L24: 1321 | O24: `
B25: Other fixed assets | C25: 43 | D25: 46 | E25: 112 | F25: 113 | G25: 125 | H25: 139 | I25: 146 | J25: 149 | K25: 154 | L25: 164
B26: Gross Block | C26: 2541 | D26: 2484 | E26: 2843 | F26: 3046 | G26: 3139 | H26: 3629 | I26: 3779 | J26: 4041 | K26: 5583 | L26: 6215
B27: Accumulated Depreciation | C27: 664 | D27: 816 | E27: 884 | F27: 1018 | G27: 1170 | H27: 1377 | I27: 1536 | J27: 1733 | K27: 2004 | L27: 2400
B28: CWIP | C28: 50 | D28: 45 | E28: 42 | F28: 42 | G28: 64 | H28: 147 | I28: 147 | J28: 168 | K28: 175 | L28: 232
B29: Investments | C29: 1813 | D29: 2691 | E29: 3240 | F29: 3805 | G29: 3359 | H29: 2800 | I29: 4160 | J29: 6220 | K29: 6265 | L29: 6933
B30: Other Assets -
B31: Inventories | C31: 973 | D31: 1096 | E31: 1107 | F31: 1256 | G31: 1301 | H31: 1380 | I31: 1734 | J31: 1911 | K31: 2024 | L31: 1947
B32: Trade receivables | C32: 711 | D32: 809 | E32: 650 | F32: 706 | G32: 834 | H32: 814 | I32: 562 | J32: 646 | K32: 849 | L32: 899
B33: Cash Equivalents | C33: 276 | D33: 220 | E33: 305 | F33: 306 | G33: 328 | H33: 811 | I33: 1329 | J33: 570 | K33: 326 | L33: 666
B34: Short term loans | C34: 63 | D34: 19 | E34: 14 | F34: 17 | G34: 22 | H34: 23 | I34: 20 | J34: 24 | K34: 33 | L34: 45
B35: Other asset items | C35: 343 | D35: 385 | E35: 416 | F35: 542 | G35: 561 | H35: 1109 | I35: 639 | J35: 437 | K35: 401 | L35: 579
B36: Total Assets | C36: =C15 -> 6107 | D36: =D15 -> 6932 | E36: =E15 -> 7731 | F36: =F15 -> 8701 | G36: =G15 -> 8436 | H36: =H15 -> 9336 | I36: =I15 -> 10834 | J36: =J15 -> 12284 | ... L36: =L15 -> 15117
B38: Cash Flow Statements
B39: Particulars | E39: 42064 | F39: 42430 | G39: 42795 | H39: 43160 | I39: 43525 | J39: 43891 | K39: 44256 | L39: 44621 | M39: 44986 | N39: 45352
B40: Cash from operating activities | E40: 1047 | F40: 1187 | G40: 1227 | H40: 1092 | I40: 1499 | J40: 1614 | K40: 2115 | L40: 1802 | M40: 1488 | N40: 2013
B41: Profit from operations | E41: 1394 | F41: 1543 | G41: 1462 | H41: 1678 | I41: 1868 | J41: 1981 | K41: 2048 | L41: 2287 | M41: 2143 | N41: 2406
B42: Receivables | E42: -142 | F42: -14 | G42: 115 | H42: -60 | I42: -130 | J42: 14 | K42: 248 | L42: -78 | M42: -191 | N42: -55
B43: Inventory | E43: -1 | F43: -123 | G43: -10 | H43: -149 | I43: -44 | J43: -79 | K43: -355 | L43: -177 | M43: -96 | N43: 77
...

Sheet Data Sheet
A1: COMPANY NAME | B1: DABUR INDIA LTD | E1: =IF(B2<>B3, "A NEW VERSION OF THE WORKSHEET IS AVAILABLE", "")
A2: LATEST VERSION | B2: 2.1 | E2: PLEASE DO NOT MAKE ANY CHANGES TO THIS SHEET
A3: CURRENT VERSION | B3: 2.1
A5: META
A6: Number of shares | B6: =IF(B9>0, B9/B8, 0) -> 177.23104
A7: Face Value | B7: 1
A8: Current Price | B8: 625.7
A9: Market Capitalization | B9: 110893.46
A15: PROFIT & LOSS
A16: Report Date | B16: 42094 | C16: 42460 | D16: 42825 | E16: 43190 | F16: 43555 | G16: 43921 | H16: 44286 | I16: 44651 | J16: 45016 | K16: 45382
A17: Sales | B17: 7795.49 | C17: 7779.66 | D17: 7613.59 | E17: 7721.85 | F17: 8514.99 | G17: 8684.64 | H17: 9561.65 | I17: 10888.68 | J17: 11529.89 | K17: 12404.01
A18: Raw Material Cost | B18: 2633.97 | C18: 2739.77 | D18: 2659.55 | E18: 2775.35 | F18: 3067.95 | G18: 3138.49 | H18: 3764.3 | I18: 4136.7 | J18: 4762.03 | K18: 4714.88
A19: Change in Inventory | B19: 25.91 | C19: 70.53 | D19: 23.02 | E19: 65.93 | F19: -12.64 | G19: 65.04 | H19: 207.2 | I19: 8.55 | J19: 90.79 | K19: -48.95
A20: Power and Fuel | B20: 90.35 | C20: 84 | D20: 87.48 | E20: 93.91 | F20: 105.26 | G20: 107.12 | H20: 104.01 | I20: 128.66 | J20: 150.59 | K20: 153.44
A21: Other Mfr. Exp | B21: 1208.32 | C21: 1180.31 | D21: 1247.42 | E21: 1219 | F21: 1327.63 | G21: 1387.98 | H21: 1347.34 | I21: 1656.53 | J21: 1779.91 | K21: 1856.5
A22: Employee Cost | B22: 690.17 | C22: 794.1 | D22: 790.3 | E22: 793.36 | F22: 938.55 | G22: 949.16 | H22: 1034.9 | I22: 1081.39 | J22: 1138.43 | K22: 1241.06
A23: Selling and admin | B23: 1640.96 | C23: 1217.44 | D23: 1161.4 | E23: 1135.38 | F23: 1183.56 | G23: 1224.59 | H23: 1388.27 | I23: 1480.71 | J23: 1426.95 | K23: 1779.99
A24: Other Expenses | B24: 237.41 | C24: 316.29 | D24: 178.85 | E24: 153.34 | F24: 139.84 | G24: 150 | H24: 128.36 | I24: 161.23 | J24: 200.28 | K24: 209.47
A25: Other Income | B25: 154.24 | C25: 217.19 | D25: 295.93 | E25: 290.88 | F25: 221.79 | G25: 205.29 | H25: 325.29 | I25: 308.16 | J25: 445.39 | K25: 482.41
A26: Depreciation | B26: 114.98 | C26: 133.19 | D26: 142.86 | E26: 162.18 | F26: 176.9 | G26: 220.45 | H26: 240.13 | I26: 252.89 | J26: 310.96 | K26: 399.21
A27: Interest | B27: 40.12 | C27: 48.48 | D27: 54.03 | E27: 53.05 | F27: 59.58 | G27: 49.54 | H27: 30.81 | I27: 38.6 | J27: 78.24 | K27: 124.18
... A31: Dividend Amount | B31: 351.3 | C31: 395.8 | D31: 396.34 | E31: 1100.94 | F31: 485.73 | G31: 530.13 | H31: 839.52 | I31: 919.31 | J31: 921.34 | K31: 974.6
A40: Quarters
A41: Report Date | B41: 44651 | C41: 44742 | D41: 44834 | E41: 44926 | F41: 45016 | G41: 45107 | H41: 45199 | I41: 45291 | J41: 45382 | K41: 45473
A42: Sales | B42: 2517.81 | C42: 2822.43 | D42: 2986.49 | E42: 3043.17 | F42: 2677.8 | G42: 3130.47 | H42: 3203.84 | I42: 3255.06 | J42: 2814.64 | K42: 3349.11
A43: Expenses | B43: 2065.44 | C43: 2279.11 | D43: 2386.09 | E43: 2434.05 | F43: 2268.15 | G43: 2525.94 | H43: 2542.97 | I43: 2587.64 | J43: 2348.23 | K43: 2694.28
A44: Other Income | B44: 14.14 | C44: 100.55 | D44: 123.28 | E44: 100.84 | F44: 120.72 | G44: 109.78 | H44: 116.9 | I44: 127.37 | J44: 128.85 | K44: 129.4
A45: Depreciation | B45: 65.05 | C45: 67.6 | D45: 70.47 | E45: 70.89 | F45: 102 | G45: 96.64 | H45: 98.32 | I45: 96.89 | J45: 107.36 | K45: 109.12
A46: Interest | B46: 11.75 | C46: 12.15 | D46: 15.06 | E46: 18.91 | F46: 32.12 | G46: 24.31 | H46: 28.14 | I46: 36.49 | J46: 35.24 | K46: 32.66
A47: Profit before tax | B47: 389.71 | C47: 564.12 | D47: 638.15 | E47: 620.16 | F47: 396.25 | G47: 593.36 | H47: 651.31 | I47: 661.41 | J47: 452.66 | K47: 642.45
A48: Tax | B48: 95.37 | C48: 123.06 | D48: 147.29 | E48: 143.51 | F48: 103.49 | G48: 136.75 | H48: 144.27 | I48: 154.97 | J48: 111.44 | K48: 148.1
A49: Net profit | B49: 294.22 | C49: 440.32 | D49: 490.06 | E49: 475.94 | F49: 300.83 | G49: 463.88 | H49: 515.05 | I49: 514.22 | J49: 349.53 | K49: 500.12
A50: Operating Profit | B50: 452.37 | C50: 543.32 | D50: 600.4 | E50: 609.12 | F50: 409.65 | G50: 604.53 | H50: 660.87 | I50: 667.42 | J50: 466.41 | K50: 654.83
A55: BALANCE SHEET
A56: Report Date | B56: 42094 | C56: 42460 | D56: 42825 | E56: 43190 | F56: 43555 | G56: 43921 | H56: 44286 | I56: 44651 | J56: 45016 | K56: 45382
A57: Equity Share Capital | B57: 175.65 | C57: 175.91 | D57: 176.15 | E57: 176.15 | F57: 176.63 | G57: 176.71 | H57: 176.74 | I57: 176.79 | J57: 177.18 | K57: 177.2
A58: Reserves | B58: 3178.49 | C58: 3994.7 | D58: 4671.24 | E58: 5530.37 | F58: 5455.05 | G58: 6429.04 | H58: 7486.79 | I58: 8204.51 | J58: 8796.08 | K58: 9689.1
A59: Borrowings | B59: 733.56 | C59: 805.22 | D59: 975 | E59: 937.59 | F59: 699.37 | G59: 521.99 | H59: 509.06 | I59: 1030.1 | J59: 1173.79 | K59: 1365.09
A60: Other Liabilities | B60: 2018.58 | C60: 1956.47 | D60: 1909.85 | E60: 2057.52 | F60: 2105.59 | G60: 2208.84 | H60: 2660.63 | I60: 2872.46 | J60: 3505.23 | K60: 3884.97
A61: Total | B61: 6106.28 | C61: 6932.3 | D61: 7732.24 | E61: 8701.63 | F61: 8436.64 | G61: 9336.58 | H61: 10833.22 | I61: 12283.86 | J61: 13652.28 | K61: 15116.36
...

Sheet Financials>

Sheet Historical FS
B2: DABUR INDIA LTD
B4: BSE : 500096 | NSE : DABUR
B6: ="Financial Statement Analysis - " & 'Data Sheet'!B1 -> Financial Statement Analysis - DABUR INDIA LTD
B7: Years | C7: ='Data Sheet'!B16 -> 42094 | D7: ='Data Sheet'!C16 -> 42460 | E7: ='Data Sheet'!D16 -> 42825 | F7: ='Data Sheet'!E16 -> 43190 | G7: ='Data Sheet'!F16 -> 43555 | H7: ='Data Sheet'!G16 -> 43921 | I7: ='Data Sheet'!H16 -> 44286 | J7: ='Data Sheet'!I16 -> 44651 | ... L7: ='Data Sheet'!K16 -> 45382 | M7: LTM
A9: # | B9: Income Statement
B10: Sales | C10: =IFERROR('Data Sheet'!B17,0) -> 7795.49 | D10: =IFERROR('Data Sheet'!C17,0) -> 7779.66 | E10: =IFERROR('Data Sheet'!D17,0) -> 7613.59 | F10: =IFERROR('Data Sheet'!E17,0) -> 7721.85 | G10: =IFERROR('Data Sheet'!F17,0) -> 8514.99 | H10: =IFERROR('Data Sheet'!G17,0) -> 8684.64 | I10: =IFERROR('Data Sheet'!H17,0) -> 9561.65 | J10: =IFERROR('Data Sheet'!I17,0) -> 10888.68 | ... L10: =IFERROR('Data Sheet'!K17,0) -> 12404.01
B11: Sales Growth | C11: - | D11: =D10/C10-1 -> -0.0020306613 | E11: =E10/D10-1 -> -0.021346691 | F11: =F10/E10-1 -> 0.01421931 | G11: =G10/F10-1 -> 0.10271373 | H11: =H10/G10-1 -> 0.019923688 | I11: =I10/H10-1 -> 0.10098404 | J11: =J10/I10-1 -> 0.13878672 | K11: =K10/J10-1 -> 0.058887762 | L11: =L10/K10-1 -> 0.075813386
B13: COGS | C13: =IFERROR(SUM('Data Sheet'!B18,'Data Sheet'!B20:B22)-1*'Data Sheet'!B19,0) -> 4596.9 | D13: =IFERROR(SUM('Data Sheet'!C18,'Data Sheet'!C20:C22)-1*'Data Sheet'!C19,0) -> 4727.65 | E13: =IFERROR(SUM('Data Sheet'!D18,'Data Sheet'!D20:D22)-1*'Data Sheet'!D19,0) -> 4761.73 | F13: =IFERROR(SUM('Data Sheet'!E18,'Data Sheet'!E20:E22)-1*'Data Sheet'!E19,0) -> 4815.69 | G13: =IFERROR(SUM('Data Sheet'!F18,'Data Sheet'!F20:F22)-1*'Data Sheet'!F19,0) -> 5452.03 | H13: =IFERROR(SUM('Data Sheet'!G18,'Data Sheet'!G20:G22)-1*'Data Sheet'!G19,0) -> 5517.71 | I13: =IFERROR(SUM('Data Sheet'!H18,'Data Sheet'!H20:H22)-1*'Data Sheet'!H19,0) -> 6043.35 | J13: =IFERROR(SUM('Data Sheet'!I18,'Data Sheet'!I20:I22)-1*'Data Sheet'!I19,0) -> 6994.73 | ... L13: =IFERROR(SUM('Data Sheet'!K18,'Data Sheet'!K20:K22)-1*'Data Sheet'!K19,0) -> 8014.83
B14: COGS % Sales | C14: =C13/C10 -> 0.58968711 | D14: =D13/D10 -> 0.60769365 | E14: =E13/E10 -> 0.62542506 | F14: =F13/F10 -> 0.62364459 | G14: =G13/G10 -> 0.64028613 | H14: =H13/H10 -> 0.63534125 | I14: =I13/I10 -> 0.6320405 | J14: =J13/J10 -> 0.64238549 | ... L14: =L13/L10 -> 0.6461483
B16: Gross Profit | C16: =C10-C13 -> 3198.59 | D16: =D10-D13 -> 3052.01 | E16: =E10-E13 -> 2851.86 | F16: =F10-F13 -> 2906.16 | G16: =G10-G13 -> 3062.96 | H16: =H10-H13 -> 3166.93 | I16: =I10-I13 -> 3518.3 | J16: =J10-J13 -> 3893.95 | ... L16: =L10-L13 -> 4389.18
B17: Gross Profit % Sales | C17: =C16/C10 -> 0.41031289 | D17: =D16/D10 -> 0.39230635 | E17: =E16/E10 -> 0.37457494 | F17: =F16/F10 -> 0.37635541 | G17: =G16/G10 -> 0.35971387 | H17: =H16/H10 -> 0.36465875 | I17: =I16/I10 -> 0.3679595 | J17: =J16/J10 -> 0.35761451 | ... L17: =L16/L10 -> 0.3538517
B19: Selling & General Expenses | C19: =IFERROR(SUM('Data Sheet'!B23:B24),0) -> 1878.37 | D19: =IFERROR(SUM('Data Sheet'!C23:C24),0) -> 1533.73 | E19: =IFERROR(SUM('Data Sheet'!D23:D24),0) -> 1340.25 | F19: =IFERROR(SUM('Data Sheet'!E23:E24),0) -> 1288.72 | G19: =IFERROR(SUM('Data Sheet'!F23:F24),0) -> 1323.4 | H19: =IFERROR(SUM('Data Sheet'!G23:G24),0) -> 1374.59 | I19: =IFERROR(SUM('Data Sheet'!H23:H24),0) -> 1516.63 | J19: =IFERROR(SUM('Data Sheet'!I23:I24),0) -> 1641.94 | ... L19: =IFERROR(SUM('Data Sheet'!K23:K24),0) -> 1989.46
B20: S&G Expenses % Sales | C20: =C19/C10 -> 0.24095599 | D20: =D19/D10 -> 0.19714615 | E20: =E19/E10 -> 0.17603391 | F20: =F19/F10 -> 0.16689265 | G20: =G19/G10 -> 0.15542003 | H20: =H19/H10 -> 0.15827829 | I20: =I19/I10 -> 0.15861593 | J20: =J19/J10 -> 0.1507933 | ... L20: =L19/L10 -> 0.16038846
B22: EBITDA | C22: =C16-C19 -> 1320.22 | D22: =D16-D19 -> 1518.28 | E22: =E16-E19 -> 1511.61 | F22: =F16-F19 -> 1617.44 | G22: =G16-G19 -> 1739.56 | H22: =H16-H19 -> 1792.34 | I22: =I16-I19 -> 2001.67 | J22: =J16-J19 -> 2252.01 | ... L22: =L16-L19 -> 2399.72
B23: EBITDA Margins | C23: =C22/C10 -> 0.1693569 | D23: =D22/D10 -> 0.1951602 | E23: =E22/E10 -> 0.19854103 | F23: =F22/F10 -> 0.20946276 | G23: =G22/G10 -> 0.20429384 | H23: =H22/H10 -> 0.20638046 | I23: =I22/I10 -> 0.20934358 | J23: =J22/J10 -> 0.20682121 | ... L23: =L22/L10 -> 0.19346324
B25: Interest | C25: =IFERROR('Data Sheet'!B27,0) -> 40.12 | D25: =IFERROR('Data Sheet'!C27,0) -> 48.48 | E25: =IFERROR('Data Sheet'!D27,0) -> 54.03 | F25: =IFERROR('Data Sheet'!E27,0) -> 53.05 | G25: =IFERROR('Data Sheet'!F27,0) -> 59.58 | H25: =IFERROR('Data Sheet'!G27,0) -> 49.54 | I25: =IFERROR('Data Sheet'!H27,0) -> 30.81 | J25: =IFERROR('Data Sheet'!I27,0) -> 38.6 | ... L25: =IFERROR('Data Sheet'!K27,0) -> 124.18
B26: Interest % Sales | C26: =C25/C10 -> 0.0051465655 | D26: =D25/D10 -> 0.0062316348 | E26: =E25/E10 -> 0.0070965208 | F26: =F25/F10 -> 0.0068701153 | G26: =G25/G10 -> 0.0069970722 | H26: =H25/H10 -> 0.005704324 | I26: =I25/I10 -> 0.0032222472 | J26: =J25/J10 -> 0.003544966 | ... L26: =L25/L10 -> 0.010011279
B28: Depreciation | C28: =IFERROR('Data Sheet'!B26,0) -> 114.98 | D28: =IFERROR('Data Sheet'!C26,0) -> 133.19 | E28: =IFERROR('Data Sheet'!D26,0) -> 142.86 | F28: =IFERROR('Data Sheet'!E26,0) -> 162.18 | G28: =IFERROR('Data Sheet'!F26,0) -> 176.9 | H28: =IFERROR('Data Sheet'!G26,0) -> 220.45 | I28: =IFERROR('Data Sheet'!H26,0) -> 240.13 | J28: =IFERROR('Data Sheet'!I26,0) -> 252.89 | ... L28: =IFERROR('Data Sheet'!K26,0) -> 399.21
B29: Depreciation % Sales | C29: =C28/C10 -> 0.014749554 | D29: =D28/D10 -> 0.017120285 | E29: =E28/E10 -> 0.018763816 | F29: =F28/F10 -> 0.021002739 | G29: =G28/G10 -> 0.020775127 | H29: =H28/H10 -> 0.025383896 | I29: =I28/I10 -> 0.025113866 | J29: =J28/J10 -> 0.023225037 | ... L29: =L28/L10 -> 0.032183947
B31: Earning Before Tax | C31: =IFERROR(C22-SUM(C28,C25),0) -> 1165.12 | D31: =IFERROR(D22-SUM(D28,D25),0) -> 1336.61 | E31: =IFERROR(E22-SUM(E28,E25),0) -> 1314.72 | F31: =IFERROR(F22-SUM(F28,F25),0) -> 1402.21 | G31: =IFERROR(G22-SUM(G28,G25),0) -> 1503.08 | H31: =IFERROR(H22-SUM(H28,H25),0) -> 1522.35 | I31: =IFERROR(I22-SUM(I28,I25),0) -> 1730.73 | J31: =IFERROR(J22-SUM(J28,J25),0) -> 1960.52 | ... L31: =IFERROR(L22-SUM(L28,L25),0) -> 1876.33
B32: EBT % Sales | C32: =C31/C10 -> 0.14946078 | D32: =D31/D10 -> 0.17180828 | E32: =E31/E10 -> 0.17268069 | F32: =F31/F10 -> 0.1815899 | G32: =G31/G10 -> 0.17652164 | H32: =H31/H10 -> 0.17529224 | I32: =I31/I10 -> 0.18100746 | J32: =J31/J10 -> 0.18005121 | ... L32: =L31/L10 -> 0.15126802
B34: Tax | C34: =IFERROR('Data Sheet'!B29,0) -> 250.89 | D34: =IFERROR('Data Sheet'!C29,0) -> 299.9 | E34: =IFERROR('Data Sheet'!D29,0) -> 330.34 | F34: =IFERROR('Data Sheet'!E29,0) -> 335.35 | G34: =IFERROR('Data Sheet'!F29,0) -> 278.62 | H34: =IFERROR('Data Sheet'!G29,0) -> 279.72 | I34: =IFERROR('Data Sheet'!H29,0) -> 361.07 | J34: =IFERROR('Data Sheet'!I29,0) -> 526.38 | ... L34: =IFERROR('Data Sheet'!K29,0) -> 547.43
B35: Effective Tax Rate | C35: =C34/C31 -> 0.21533404 | D35: =D34/D31 -> 0.2243736 | E35: =E34/E31 -> 0.25126263 | F35: =F34/F31 -> 0.23915819 | G35: =G34/G31 -> 0.18536605 | H35: =H34/H31 -> 0.18374224 | I35: =I34/I31 -> 0.20862295 | J35: =J34/J31 -> 0.26848999 | ... L35: =L34/L31 -> 0.29175571
B37: Net Profit | C37: =IFERROR(C31-C34,0) -> 914.23 | D37: =IFERROR(D31-D34,0) -> 1036.71 | E37: =IFERROR(E31-E34,0) -> 984.38 | F37: =IFERROR(F31-F34,0) -> 1066.86 | G37: =IFERROR(G31-G34,0) -> 1224.46 | H37: =IFERROR(H31-H34,0) -> 1242.63 | I37: =IFERROR(I31-I34,0) -> 1369.66 | J37: =IFERROR(J31-J34,0) -> 1434.14 | ... L37: =IFERROR(L31-L34,0) -> 1328.9
B38: Net Margins | C38: =C37/C10 -> 0.11727678 | D38: =D37/D10 -> 0.13325904 | E38: =E37/E10 -> 0.12929249 | F38: =F37/F10 -> 0.13816119 | G38: =G37/G10 -> 0.14380052 | H38: =H37/H10 -> 0.14308365 | I38: =I37/I10 -> 0.14324515 | J38: =J37/J10 -> 0.13170926 | ... L38: =L37/L10 -> 0.10713471
B40: No. of Equity Shares | C40: =IFERROR('Data Sheet'!B93,0) -> 175.65 | D40: =IFERROR('Data Sheet'!C93,0) -> 175.91 | E40: =IFERROR('Data Sheet'!D93,0) -> 176.15 | F40: =IFERROR('Data Sheet'!E93,0) -> 176.15 | G40: =IFERROR('Data Sheet'!F93,0) -> 176.63 | H40: =IFERROR('Data Sheet'!G93,0) -> 176.71 | I40: =IFERROR('Data Sheet'!H93,0) -> 176.74 | J40: =IFERROR('Data Sheet'!I93,0) -> 176.79 | ... L40: =IFERROR('Data Sheet'!K93,0) -> 177.2
B42: Earning Per Share | C42: =IFERROR(C37/C40,0) -> 5.2048392 | D42: =IFERROR(D37/D40,0) -> 5.8934114 | E42: =IFERROR(E37/E40,0) -> 5.5883054 | F42: =IFERROR(F37/F40,0) -> 6.0565427 | G42: =IFERROR(G37/G40,0) -> 6.9323444 | H42: =IFERROR(H37/H40,0) -> 7.0320299 | I42: =IFERROR(I37/I40,0) -> 7.7495756 | J42: =IFERROR(J37/J40,0) -> 8.1121104 | ... L42: =IFERROR(L37/L40,0) -> 7.4994357
B43: EPS Growth | C43: - | D43: =IFERROR(D42/C42-1,0) -> 0.13229462 | E43: =IFERROR(E42/D42-1,0) -> -0.051770691 | F43: =IFERROR(F42/E42-1,0) -> 0.083788781 | G43: =IFERROR(G42/F42-1,0) -> 0.14460424 | H43: =IFERROR(H42/G42-1,0) -> 0.014379757 | I43: =IFERROR(I42/H42-1,0) -> 0.10203964 | J43: =IFERROR(J42/I42-1,0) -> 0.046781241 | K43: =IFERROR(K42/J42-1,0) -> -0.1261833 | L43: =IFERROR(L42/K42-1,0) -> 0.057972524
B45: Dividend Per Share | C45: =IFERROR('Data Sheet'!B31/'Data Sheet'!B93,0) -> 2 | D45: =IFERROR('Data Sheet'!C31/'Data Sheet'!C93,0) -> 2.2500142 | E45: =IFERROR('Data Sheet'!D31/'Data Sheet'!D93,0) -> 2.2500142 | F45: =IFERROR('Data Sheet'!E31/'Data Sheet'!E93,0) -> 6.2500142 | G45: =IFERROR('Data Sheet'!F31/'Data Sheet'!F93,0) -> 2.7499858 | H45: =IFERROR('Data Sheet'!G31/'Data Sheet'!G93,0) -> 3 | I45: =IFERROR('Data Sheet'!H31/'Data Sheet'!H93,0) -> 4.7500283 | J45: =IFERROR('Data Sheet'!I31/'Data Sheet'!I93,0) -> 5.2000113 | ... L45: =IFERROR('Data Sheet'!K31/'Data Sheet'!K93,0) -> 5.5
B46: Dividend Payout Ratio | C46: =C45/C42 -> 0.38425779 | D46: =D45/D42 -> 0.38178468 | E46: =E45/E42 -> 0.40262907 | F46: =F45/F42 -> 1.0319442 | G46: =G45/G42 -> 0.39668915 | H46: =H45/H42 -> 0.42661935 | I46: =I45/I42 -> 0.61294044 | J46: =J45/J42 -> 0.64101831 | ... L46: =L45/L42 -> 0.73338852
B48: Retained Earning | C48: =IFERROR(IF(C42>C45,1-C46,0),0) -> 0.61574221 | D48: =IFERROR(IF(D42>D45,1-D46,0),0) -> 0.61821532 | E48: =IFERROR(IF(E42>E45,1-E46,0),0) -> 0.59737093 | F48: =IFERROR(IF(F42>F45,1-F46,0),0) -> 0 | G48: =IFERROR(IF(G42>G45,1-G46,0),0) -> 0.60331085 | H48: =IFERROR(IF(H42>H45,1-H46,0),0) -> 0.57338065 | I48: =IFERROR(IF(I42>I45,1-I46,0),0) -> 0.38705956 | J48: =IFERROR(IF(J42>J45,1-J46,0),0) -> 0.35898169 | ... L48: =IFERROR(IF(L42>L45,1-L46,0),0) -> 0.26661148
A50: # | B50: Balance Sheet
B51: Equity Share Capital | C51: =IFERROR('Data Sheet'!B57,0) -> 175.65 | D51: =IFERROR('Data Sheet'!C57,0) -> 175.91 | E51: =IFERROR('Data Sheet'!D57,0) -> 176.15 | F51: =IFERROR('Data Sheet'!E57,0) -> 176.15 | G51: =IFERROR('Data Sheet'!F57,0) -> 176.63 | H51: =IFERROR('Data Sheet'!G57,0) -> 176.71 | I51: =IFERROR('Data Sheet'!H57,0) -> 176.74 | J51: =IFERROR('Data Sheet'!I57,0) -> 176.79 | ... L51: =IFERROR('Data Sheet'!K57,0) -> 177.2
B52: Reserves | C52: =IFERROR('Data Sheet'!B58,0) -> 3178.49 | D52: =IFERROR('Data Sheet'!C58,0) -> 3994.7 | E52: =IFERROR('Data Sheet'!D58,0) -> 4671.24 | F52: =IFERROR('Data Sheet'!E58,0) -> 5530.37 | G52: =IFERROR('Data Sheet'!F58,0) -> 5455.05 | H52: =IFERROR('Data Sheet'!G58,0) -> 6429.04 | I52: =IFERROR('Data Sheet'!H58,0) -> 7486.79 | J52: =IFERROR('Data Sheet'!I58,0) -> 8204.51 | ... L52: =IFERROR('Data Sheet'!K58,0) -> 9689.1
B53: Borrowings | C53: =IFERROR('Data Sheet'!B59,0) -> 733.56 | D53: =IFERROR('Data Sheet'!C59,0) -> 805.22 | E53: =IFERROR('Data Sheet'!D59,0) -> 975 | F53: =IFERROR('Data Sheet'!E59,0) -> 937.59 | G53: =IFERROR('Data Sheet'!F59,0) -> 699.37 | H53: =IFERROR('Data Sheet'!G59,0) -> 521.99 | I53: =IFERROR('Data Sheet'!H59,0) -> 509.06 | J53: =IFERROR('Data Sheet'!I59,0) -> 1030.1 | ... L53: =IFERROR('Data Sheet'!K59,0) -> 1365.09
B54: Other Liabilities | C54: =IFERROR('Data Sheet'!B60,0) -> 2018.58 | D54: =IFERROR('Data Sheet'!C60,0) -> 1956.47 | E54: =IFERROR('Data Sheet'!D60,0) -> 1909.85 | F54: =IFERROR('Data Sheet'!E60,0) -> 2057.52 | G54: =IFERROR('Data Sheet'!F60,0) -> 2105.59 | H54: =IFERROR('Data Sheet'!G60,0) -> 2208.84 | I54: =IFERROR('Data Sheet'!H60,0) -> 2660.63 | J54: =IFERROR('Data Sheet'!I60,0) -> 2872.46 | ... L54: =IFERROR('Data Sheet'!K60,0) -> 3884.97
B55: Total Liabilities | C55: =IFERROR('Data Sheet'!B61,0) -> 6106.28 | D55: =IFERROR('Data Sheet'!C61,0) -> 6932.3 | E55: =IFERROR('Data Sheet'!D61,0) -> 7732.24 | F55: =IFERROR('Data Sheet'!E61,0) -> 8701.63 | G55: =IFERROR('Data Sheet'!F61,0) -> 8436.64 | H55: =IFERROR('Data Sheet'!G61,0) -> 9336.58 | I55: =IFERROR('Data Sheet'!H61,0) -> 10833.22 | J55: =IFERROR('Data Sheet'!I61,0) -> 12283.86 | ... L55: =IFERROR('Data Sheet'!K61,0) -> 15116.36
B57: Net Block | C57: =IFERROR('Data Sheet'!B62,0) -> 1877.13 | D57: =IFERROR('Data Sheet'!C62,0) -> 1667.4 | E57: =IFERROR('Data Sheet'!D62,0) -> 1958.4 | F57: =IFERROR('Data Sheet'!E62,0) -> 2028.11 | G57: =IFERROR('Data Sheet'!F62,0) -> 1969.06 | H57: =IFERROR('Data Sheet'!G62,0) -> 2252.68 | I57: =IFERROR('Data Sheet'!H62,0) -> 2242.92 | J57: =IFERROR('Data Sheet'!I62,0) -> 2307.9 | ... L57: =IFERROR('Data Sheet'!K62,0) -> 3815
B58: Capital Work in Progress | C58: =IFERROR('Data Sheet'!B63,0) -> 50.3 | D58: =IFERROR('Data Sheet'!C63,0) -> 44.8 | E58: =IFERROR('Data Sheet'!D63,0) -> 42.1 | F58: =IFERROR('Data Sheet'!E63,0) -> 41.51 | G58: =IFERROR('Data Sheet'!F63,0) -> 63.76 | H58: =IFERROR('Data Sheet'!G63,0) -> 146.57 | I58: =IFERROR('Data Sheet'!H63,0) -> 147.3 | J58: =IFERROR('Data Sheet'!I63,0) -> 167.5 | ... L58: =IFERROR('Data Sheet'!K63,0) -> 232.23
B59: Investments | C59: =IFERROR('Data Sheet'!B64,0) -> 1813.37 | D59: =IFERROR('Data Sheet'!C64,0) -> 2690.74 | E59: =IFERROR('Data Sheet'!D64,0) -> 3240.16 | F59: =IFERROR('Data Sheet'!E64,0) -> 3805.17 | G59: =IFERROR('Data Sheet'!F64,0) -> 3358.76 | H59: =IFERROR('Data Sheet'!G64,0) -> 2800.26 | I59: =IFERROR('Data Sheet'!H64,0) -> 4159.63 | J59: =IFERROR('Data Sheet'!I64,0) -> 6219.62 | ... L59: =IFERROR('Data Sheet'!K64,0) -> 6932.69
...

Sheet Ratios
B2: DABUR INDIA LTD
B4: BSE : 500096 | NSE : DABUR
B6: ="Financial Statement Analysis - " & 'Data Sheet'!B1 -> Financial Statement Analysis - DABUR INDIA LTD
B7: Years | C7: ='Data Sheet'!B16 -> 42094 | D7: ='Data Sheet'!C16 -> 42460 | E7: ='Data Sheet'!D16 -> 42825 | F7: ='Data Sheet'!E16 -> 43190 | G7: ='Data Sheet'!F16 -> 43555 | H7: ='Data Sheet'!G16 -> 43921 | I7: ='Data Sheet'!H16 -> 44286 | J7: ='Data Sheet'!I16 -> 44651 | ... L7: ='Data Sheet'!K16 -> 45382 | M7: Trend | N7: Mean | O7: Median
B9: Sales Growth | C9: - | D9: =IFERROR('Historical FS'!D11,0) -> -0.0020306613 | E9: =IFERROR('Historical FS'!E11,0) -> -0.021346691 | F9: =IFERROR('Historical FS'!F11,0) -> 0.01421931 | G9: =IFERROR('Historical FS'!G11,0) -> 0.10271373 | H9: =IFERROR('Historical FS'!H11,0) -> 0.019923688 | I9: =IFERROR('Historical FS'!I11,0) -> 0.10098404 | J9: =IFERROR('Historical FS'!J11,0) -> 0.13878672 | K9: =IFERROR('Historical FS'!K11,0) -> 0.058887762 | L9: =IFERROR('Historical FS'!L11,0) -> 0.075813386 | N9: =IFERROR(AVERAGE(D9:L9),0) -> 0.054216808 | O9: =IFERROR(MEDIAN(D9:L9),0) -> 0.058887762
B10: EBITDA Growth | C10: - | D10: =IFERROR('Historical FS'!D22/'Historical FS'!C22-1,0) -> 0.15002045 | E10: =IFERROR('Historical FS'!E22/'Historical FS'!D22-1,0) -> -0.0043931291 | F10: =IFERROR('Historical FS'!F22/'Historical FS'!E22-1,0) -> 0.070011445 | G10: =IFERROR('Historical FS'!G22/'Historical FS'!F22-1,0) -> 0.075502028 | H10: =IFERROR('Historical FS'!H22/'Historical FS'!G22-1,0) -> 0.030341006 | I10: =IFERROR('Historical FS'!I22/'Historical FS'!H22-1,0) -> 0.11679146 | J10: =IFERROR('Historical FS'!J22/'Historical FS'!I22-1,0) -> 0.12506557 | K10: =IFERROR('Historical FS'!K22/'Historical FS'!J22-1,0) -> -0.039751156 | L10: =IFERROR('Historical FS'!L22/'Historical FS'!K22-1,0) -> 0.10970224 | N10: =IFERROR(AVERAGE(D10:L10),0) -> 0.070365546 | O10: =IFERROR(MEDIAN(D10:L10),0) -> 0.075502028
B11: EBIT Growth | C11: - | D11: =IFERROR('Historical FS'!D31/'Historical FS'!C31-1,0) -> 0.14718656 | E11: =IFERROR('Historical FS'!E31/'Historical FS'!D31-1,0) -> -0.016377253 | F11: =IFERROR('Historical FS'!F31/'Historical FS'!E31-1,0) -> 0.066546489 | G11: =IFERROR('Historical FS'!G31/'Historical FS'!F31-1,0) -> 0.071936443 | H11: =IFERROR('Historical FS'!H31/'Historical FS'!G31-1,0) -> 0.012820342 | I11: =IFERROR('Historical FS'!I31/'Historical FS'!H31-1,0) -> 0.13688048 | J11: =IFERROR('Historical FS'!J31/'Historical FS'!I31-1,0) -> 0.13277057 | K11: =IFERROR('Historical FS'!K31/'Historical FS'!J31-1,0) -> -0.095500173 | L11: =IFERROR('Historical FS'!L31/'Historical FS'!K31-1,0) -> 0.058106683 | N11: =IFERROR(AVERAGE(D11:L11),0) -> 0.057152237 | O11: =IFERROR(MEDIAN(D11:L11),0) -> 0.066546489
B12: Net Profit Growth | C12: - | D12: =IFERROR('Historical FS'!D37/'Historical FS'!C37-1,0) -> 0.13397066 | E12: =IFERROR('Historical FS'!E37/'Historical FS'!D37-1,0) -> -0.05047699 | F12: =IFERROR('Historical FS'!F37/'Historical FS'!E37-1,0) -> 0.083788781 | G12: =IFERROR('Historical FS'!G37/'Historical FS'!F37-1,0) -> 0.14772323 | H12: =IFERROR('Historical FS'!H37/'Historical FS'!G37-1,0) -> 0.014839194 | I12: =IFERROR('Historical FS'!I37/'Historical FS'!H37-1,0) -> 0.10222673 | J12: =IFERROR('Historical FS'!J37/'Historical FS'!I37-1,0) -> 0.047077377 | K12: =IFERROR('Historical FS'!K37/'Historical FS'!J37-1,0) -> -0.12425565 | L12: =IFERROR('Historical FS'!L37/'Historical FS'!K37-1,0) -> 0.058091947 | N12: =IFERROR(AVERAGE(D12:L12),0) -> 0.045887253 | O12: =IFERROR(MEDIAN(D12:L12),0) -> 0.058091947
B13: Dividend Growth | C13: - | D13: =IFERROR('Historical FS'!D45/'Historical FS'!C45-1,0) -> 0.12500711 | E13: =IFERROR('Historical FS'!E45/'Historical FS'!D45-1,0) -> -8.6058313e-09 | F13: =IFERROR('Historical FS'!F45/'Historical FS'!E45-1,0) -> 1.7777666 | G13: =IFERROR('Historical FS'!G45/'Historical FS'!F45-1,0) -> -0.56000326 | H13: =IFERROR('Historical FS'!H45/'Historical FS'!G45-1,0) -> 0.090914706 | I13: =IFERROR('Historical FS'!I45/'Historical FS'!H45-1,0) -> 0.58334276 | J13: =IFERROR('Historical FS'!J45/'Historical FS'!I45-1,0) -> 0.094732704 | K13: =IFERROR('Historical FS'!K45/'Historical FS'!J45-1,0) -> 2.1659673e-06 | L13: =IFERROR('Historical FS'!L45/'Historical FS'!K45-1,0) -> 0.057687716 | N13: =IFERROR(AVERAGE(D13:L13),0) -> 0.24105005 | O13: =IFERROR(MEDIAN(D13:L13),0) -> 0.090914706
B15: Gross Margin | C15: =IFERROR('Historical FS'!C17,0) -> 0.41031289 | D15: =IFERROR('Historical FS'!D17,0) -> 0.39230635 | E15: =IFERROR('Historical FS'!E17,0) -> 0.37457494 | F15: =IFERROR('Historical FS'!F17,0) -> 0.37635541 | G15: =IFERROR('Historical FS'!G17,0) -> 0.35971387 | H15: =IFERROR('Historical FS'!H17,0) -> 0.36465875 | I15: =IFERROR('Historical FS'!I17,0) -> 0.3679595 | J15: =IFERROR('Historical FS'!J17,0) -> 0.35761451 | ... L15: =IFERROR('Historical FS'!L17,0) -> 0.3538517 | N15: =IFERROR(AVERAGE(C15:L15),0) -> 0.36860345 | O15: =IFERROR(MEDIAN(C15:L15),0) -> 0.36630913
B16: EBITDA Margin | C16: =IFERROR('Historical FS'!C23,0) -> 0.1693569 | D16: =IFERROR('Historical FS'!D23,0) -> 0.1951602 | E16: =IFERROR('Historical FS'!E23,0) -> 0.19854103 | F16: =IFERROR('Historical FS'!F23,0) -> 0.20946276 | G16: =IFERROR('Historical FS'!G23,0) -> 0.20429384 | H16: =IFERROR('Historical FS'!H23,0) -> 0.20638046 | I16: =IFERROR('Historical FS'!I23,0) -> 0.20934358 | J16: =IFERROR('Historical FS'!J23,0) -> 0.20682121 | ... L16: =IFERROR('Historical FS'!L23,0) -> 0.19346324 | N16: =IFERROR(AVERAGE(C16:L16),0) -> 0.19803783 | O16: =IFERROR(MEDIAN(C16:L16),0) -> 0.20141743
B17: EBIT Margin | C17: =IFERROR(('Historical FS'!C22-'Historical FS'!C28)/'Historical FS'!C10,0) -> 0.15460734 | D17: =IFERROR(('Historical FS'!D22-'Historical FS'!D28)/'Historical FS'!D10,0) -> 0.17803991 | E17: =IFERROR(('Historical FS'!E22-'Historical FS'!E28)/'Historical FS'!E10,0) -> 0.17977721 | F17: =IFERROR(('Historical FS'!F22-'Historical FS'!F28)/'Historical FS'!F10,0) -> 0.18846002 | G17: =IFERROR(('Historical FS'!G22-'Historical FS'!G28)/'Historical FS'!G10,0) -> 0.18351871 | H17: =IFERROR(('Historical FS'!H22-'Historical FS'!H28)/'Historical FS'!H10,0) -> 0.18099656 | I17: =IFERROR(('Historical FS'!I22-'Historical FS'!I28)/'Historical FS'!I10,0) -> 0.18422971 | J17: =IFERROR(('Historical FS'!J22-'Historical FS'!J28)/'Historical FS'!J10,0) -> 0.18359618 | ... L17: =IFERROR(('Historical FS'!L22-'Historical FS'!L28)/'Historical FS'!L10,0) -> 0.1612793 | N17: =IFERROR(AVERAGE(C17:L17),0) -> 0.17550902 | O17: =IFERROR(MEDIAN(C17:L17),0) -> 0.18038689
B18: EBT Margin | C18: =IFERROR('Historical FS'!C32,0) -> 0.14946078 | D18: =IFERROR('Historical FS'!D32,0) -> 0.17180828 | E18: =IFERROR('Historical FS'!E32,0) -> 0.17268069 | F18: =IFERROR('Historical FS'!F32,0) -> 0.1815899 | G18: =IFERROR('Historical FS'!G32,0) -> 0.17652164 | H18: =IFERROR('Historical FS'!H32,0) -> 0.17529224 | I18: =IFERROR('Historical FS'!I32,0) -> 0.18100746 | J18: =IFERROR('Historical FS'!J32,0) -> 0.18005121 | ... L18: =IFERROR('Historical FS'!L32,0) -> 0.15126802 | N18: =IFERROR(AVERAGE(C18:L18),0) -> 0.16934796 | O18: =IFERROR(MEDIAN(C18:L18),0) -> 0.17398647
B19: Net Profit Margin | C19: =IFERROR('Historical FS'!C38,0) -> 0.11727678 | D19: =IFERROR('Historical FS'!D38,0) -> 0.13325904 | E19: =IFERROR('Historical FS'!E38,0) -> 0.12929249 | F19: =IFERROR('Historical FS'!F38,0) -> 0.13816119 | G19: =IFERROR('Historical FS'!G38,0) -> 0.14380052 | H19: =IFERROR('Historical FS'!H38,0) -> 0.14308365 | I19: =IFERROR('Historical FS'!I38,0) -> 0.14324515 | J19: =IFERROR('Historical FS'!J38,0) -> 0.13170926 | ... L19: =IFERROR('Historical FS'!L38,0) -> 0.10713471 | N19: =IFERROR(AVERAGE(C19:L19),0) -> 0.12958918 | O19: =IFERROR(MEDIAN(C19:L19),0) -> 0.13248415
B21: SalesExpenses%Sales | C21: =IFERROR('Historical FS'!C20,0) -> 0.24095599 | D21: =IFERROR('Historical FS'!D20,0) -> 0.19714615 | E21: =IFERROR('Historical FS'!E20,0) -> 0.17603391 | F21: =IFERROR('Historical FS'!F20,0) -> 0.16689265 | G21: =IFERROR('Historical FS'!G20,0) -> 0.15542003 | H21: =IFERROR('Historical FS'!H20,0) -> 0.15827829 | I21: =IFERROR('Historical FS'!I20,0) -> 0.15861593 | J21: =IFERROR('Historical FS'!J20,0) -> 0.1507933 | ... L21: =IFERROR('Historical FS'!L20,0) -> 0.16038846 | N21: =IFERROR(AVERAGE(C21:L21),0) -> 0.17056561 | O21: =IFERROR(MEDIAN(C21:L21),0) -> 0.15950219
B22: Depreciation%Sales | C22: =IFERROR('Historical FS'!C29,0) -> 0.014749554 | D22: =IFERROR('Historical FS'!D29,0) -> 0.017120285 | E22: =IFERROR('Historical FS'!E29,0) -> 0.018763816 | F22: =IFERROR('Historical FS'!F29,0) -> 0.021002739 | G22: =IFERROR('Historical FS'!G29,0) -> 0.020775127 | H22: =IFERROR('Historical FS'!H29,0) -> 0.025383896 | I22: =IFERROR('Historical FS'!I29,0) -> 0.025113866 | J22: =IFERROR('Historical FS'!J29,0) -> 0.023225037 | ... L22: =IFERROR('Historical FS'!L29,0) -> 0.032183947 | N22: =IFERROR(AVERAGE(C22:L22),0) -> 0.022528817 | O22: =IFERROR(MEDIAN(C22:L22),0) -> 0.022113888
B23: OperatingIncome%Sales | C23: =C17 -> 0.15460734 | D23: =D17 -> 0.17803991 | E23: =E17 -> 0.17977721 | F23: =F17 -> 0.18846002 | G23: =G17 -> 0.18351871 | H23: =H17 -> 0.18099656 | I23: =I17 -> 0.18422971 | J23: =J17 -> 0.18359618 | ... L23: =L17 -> 0.1612793 | N23: =IFERROR(AVERAGE(C23:L23),0) -> 0.17550902 | O23: =IFERROR(MEDIAN(C23:L23),0) -> 0.18038689
B25: Return on Capital Employed | C25: =IFERROR(('Historical FS'!C22-'Historical FS'!C28)/SUM('Historical FS'!C51:C53),0) -> 0.29484551 | D25: =IFERROR(('Historical FS'!D22-'Historical FS'!D28)/SUM('Historical FS'!D51:D53),0) -> 0.27836361 | E25: =IFERROR(('Historical FS'!E22-'Historical FS'!E28)/SUM('Historical FS'!E51:E53),0) -> 0.23508387 | F25: =IFERROR(('Historical FS'!F22-'Historical FS'!F28)/SUM('Historical FS'!F51:F53),0) -> 0.21903009 | G25: =IFERROR(('Historical FS'!G22-'Historical FS'!G28)/SUM('Historical FS'!G51:G53),0) -> 0.24682478 | H25: =IFERROR(('Historical FS'!H22-'Historical FS'!H28)/SUM('Historical FS'!H51:H53),0) -> 0.22053133 | I25: =IFERROR(('Historical FS'!I22-'Historical FS'!I28)/SUM('Historical FS'!I51:I53),0) -> 0.21554244 | J25: =IFERROR(('Historical FS'!J22-'Historical FS'!J28)/SUM('Historical FS'!J51:J53),0) -> 0.21241473 | ... L25: =IFERROR(('Historical FS'!L22-'Historical FS'!L28)/SUM('Historical FS'!L51:L53),0) -> 0.17811776 | N25: =IFERROR(AVERAGE(C25:L25),0) -> 0.22832239 | O25: =IFERROR(MEDIAN(C25:L25),0) -> 0.21978071
B26: Retained Earnings | C26: =IFERROR('Historical FS'!C48,0) -> 0.61574221 | D26: =IFERROR('Historical FS'!D48,0) -> 0.61821532 | E26: =IFERROR('Historical FS'!E48,0) -> 0.59737093 | F26: =IFERROR('Historical FS'!F48,0) -> 0 | G26: =IFERROR('Historical FS'!G48,0) -> 0.60331085 | H26: =IFERROR('Historical FS'!H48,0) -> 0.57338065 | I26: =IFERROR('Historical FS'!I48,0) -> 0.38705956 | J26: =IFERROR('Historical FS'!J48,0) -> 0.35898169 | ... L26: =IFERROR('Historical FS'!L48,0) -> 0.26661148 | N26: =IFERROR(AVERAGE(C26:L26),0) -> 0.42870867 | O26: =IFERROR(MEDIAN(C26:L26),0) -> 0.48022011
B27: Return on Equity | C27: =IFERROR('Historical FS'!C37/SUM('Historical FS'!C51:C52),0) -> 0.27256763 | D27: =IFERROR('Historical FS'!D37/SUM('Historical FS'!D51:D52),0) -> 0.24857515 | E27: =IFERROR('Historical FS'!E37/SUM('Historical FS'!E51:E52),0) -> 0.20307423 | F27: =IFERROR('Historical FS'!F37/SUM('Historical FS'!F51:F52),0) -> 0.18695457 | G27: =IFERROR('Historical FS'!G37/SUM('Historical FS'!G51:G52),0) -> 0.21742358 | H27: =IFERROR('Historical FS'!H37/SUM('Historical FS'!H51:H52),0) -> 0.18811339 | I27: =IFERROR('Historical FS'!I37/SUM('Historical FS'!I51:I52),0) -> 0.17872443 | J27: =IFERROR('Historical FS'!J37/SUM('Historical FS'!J51:J52),0) -> 0.17111188 | ... L27: =IFERROR('Historical FS'!L37/SUM('Historical FS'!L51:L52),0) -> 0.13469082 | N27: =IFERROR(AVERAGE(C27:L27),0) -> 0.19412004 | O27: =IFERROR(MEDIAN(C27:L27),0) -> 0.18753398
